<?xml version="1.0" encoding="UTF-8"?>
<testng-results skipped="9" failed="3" ignored="0" total="12" passed="0">
  <reporter-output>
    <line>
      <![CDATA[方法<TestCase>执行失败，重试第1次]]>
    </line>
    <line>
      <![CDATA[方法<TestCase>执行失败，重试第2次]]>
    </line>
    <line>
      <![CDATA[方法<TestCase>执行失败，重试第3次]]>
    </line>
    <line>
      <![CDATA[方法<TestCase>执行失败，重试第1次]]>
    </line>
    <line>
      <![CDATA[方法<TestCase>执行失败，重试第2次]]>
    </line>
    <line>
      <![CDATA[方法<TestCase>执行失败，重试第3次]]>
    </line>
    <line>
      <![CDATA[方法<TestCase>执行失败，重试第1次]]>
    </line>
    <line>
      <![CDATA[方法<TestCase>执行失败，重试第2次]]>
    </line>
    <line>
      <![CDATA[方法<TestCase>执行失败，重试第3次]]>
    </line>
  </reporter-output>
  <suite name="testproj" duration-ms="90977" started-at="2018-01-21T08:09:51Z" finished-at="2018-01-21T08:11:22Z">
    <groups>
    </groups>
    <test name="testDemo1" duration-ms="90977" started-at="2018-01-21T08:09:51Z" finished-at="2018-01-21T08:11:22Z">
      <class name="apitest.ApiTestNgTest">
        <test-method status="SKIP" signature="TestCase(api.TestCase)[pri:0, instance:apitest.ApiTestNgTest@2e55dd0c]" name="TestCase" duration-ms="935" started-at="2018-01-21T16:09:52Z" data-provider="exceldata" finished-at="2018-01-21T16:09:53Z">
          <params>
            <param index="0">
              <value>
                <![CDATA[TestCase [type=get, url=http://59.110.139.20:8080/goods/UserServlet?method=loginMobile&loginname=test1&loginpass=test1, params=null, header=token=11;user=123;, result=null, check=$.code=1, correlation=id=$.uid]]]>
              </value>
            </param>
          </params>
          <exception class="java.lang.AssertionError">
            <message>
              <![CDATA[expected [true] but found [false]]]>
            </message>
            <full-stacktrace>
              <![CDATA[java.lang.AssertionError: expected [true] but found [false]at org.testng.Assert.fail(Assert.java:96)at org.testng.Assert.failNotEquals(Assert.java:776)at org.testng.Assert.assertTrue(Assert.java:44)at org.testng.Assert.assertTrue(Assert.java:54)at apitest.ApiTestNgTest.TestCase(ApiTestNgTest.java:42)at sun.reflect.NativeMethodAccessorImpl.invoke0(Native Method)at sun.reflect.NativeMethodAccessorImpl.invoke(NativeMethodAccessorImpl.java:62)at sun.reflect.DelegatingMethodAccessorImpl.invoke(DelegatingMethodAccessorImpl.java:43)at java.lang.reflect.Method.invoke(Method.java:483)at org.testng.internal.MethodInvocationHelper.invokeMethod(MethodInvocationHelper.java:124)at org.testng.internal.Invoker.invokeMethod(Invoker.java:571)at org.testng.internal.Invoker.invokeTestMethod(Invoker.java:707)at org.testng.internal.Invoker.invokeTestMethods(Invoker.java:979)at org.testng.internal.TestMethodWorker.invokeTestMethods(TestMethodWorker.java:125)at org.testng.internal.TestMethodWorker.run(TestMethodWorker.java:109)at org.testng.TestRunner.privateRun(TestRunner.java:648)at org.testng.TestRunner.run(TestRunner.java:505)at org.testng.SuiteRunner.runTest(SuiteRunner.java:455)at org.testng.SuiteRunner.runSequentially(SuiteRunner.java:450)at org.testng.SuiteRunner.privateRun(SuiteRunner.java:415)at org.testng.SuiteRunner.run(SuiteRunner.java:364)at org.testng.SuiteRunnerWorker.runSuite(SuiteRunnerWorker.java:52)at org.testng.SuiteRunnerWorker.run(SuiteRunnerWorker.java:84)at org.testng.TestNG.runSuitesSequentially(TestNG.java:1187)at org.testng.TestNG.runSuitesLocally(TestNG.java:1116)at org.testng.TestNG.runSuites(TestNG.java:1028)at org.testng.TestNG.run(TestNG.java:996)at org.testng.remote.AbstractRemoteTestNG.run(AbstractRemoteTestNG.java:114)at org.testng.remote.RemoteTestNG.initAndRun(RemoteTestNG.java:251)at org.testng.remote.RemoteTestNG.main(RemoteTestNG.java:77)]]>
            </full-stacktrace>
          </exception> <!-- java.lang.AssertionError -->
          <reporter-output>
            <line>
              <![CDATA[方法<TestCase>执行失败，重试第1次]]>
            </line>
          </reporter-output>
        </test-method> <!-- TestCase -->
        <test-method status="SKIP" signature="TestCase(api.TestCase)[pri:0, instance:apitest.ApiTestNgTest@2e55dd0c]" name="TestCase" duration-ms="43" started-at="2018-01-21T16:10:06Z" data-provider="exceldata" finished-at="2018-01-21T16:10:07Z">
          <params>
            <param index="0">
              <value>
                <![CDATA[TestCase [type=get, url=http://59.110.139.20:8080/goods/UserServlet?method=loginMobile&loginname=test1&loginpass=test1, params=null, header=token=11;user=123;, result=null, check=$.code=1, correlation=id=$.uid]]]>
              </value>
            </param>
          </params>
          <exception class="java.lang.AssertionError">
            <message>
              <![CDATA[expected [true] but found [false]]]>
            </message>
            <full-stacktrace>
              <![CDATA[java.lang.AssertionError: expected [true] but found [false]at org.testng.Assert.fail(Assert.java:96)at org.testng.Assert.failNotEquals(Assert.java:776)at org.testng.Assert.assertTrue(Assert.java:44)at org.testng.Assert.assertTrue(Assert.java:54)at apitest.ApiTestNgTest.TestCase(ApiTestNgTest.java:42)at sun.reflect.NativeMethodAccessorImpl.invoke0(Native Method)at sun.reflect.NativeMethodAccessorImpl.invoke(NativeMethodAccessorImpl.java:62)at sun.reflect.DelegatingMethodAccessorImpl.invoke(DelegatingMethodAccessorImpl.java:43)at java.lang.reflect.Method.invoke(Method.java:483)at org.testng.internal.MethodInvocationHelper.invokeMethod(MethodInvocationHelper.java:124)at org.testng.internal.Invoker.invokeMethod(Invoker.java:571)at org.testng.internal.Invoker.retryFailed(Invoker.java:829)at org.testng.internal.Invoker.invokeTestMethods(Invoker.java:1000)at org.testng.internal.TestMethodWorker.invokeTestMethods(TestMethodWorker.java:125)at org.testng.internal.TestMethodWorker.run(TestMethodWorker.java:109)at org.testng.TestRunner.privateRun(TestRunner.java:648)at org.testng.TestRunner.run(TestRunner.java:505)at org.testng.SuiteRunner.runTest(SuiteRunner.java:455)at org.testng.SuiteRunner.runSequentially(SuiteRunner.java:450)at org.testng.SuiteRunner.privateRun(SuiteRunner.java:415)at org.testng.SuiteRunner.run(SuiteRunner.java:364)at org.testng.SuiteRunnerWorker.runSuite(SuiteRunnerWorker.java:52)at org.testng.SuiteRunnerWorker.run(SuiteRunnerWorker.java:84)at org.testng.TestNG.runSuitesSequentially(TestNG.java:1187)at org.testng.TestNG.runSuitesLocally(TestNG.java:1116)at org.testng.TestNG.runSuites(TestNG.java:1028)at org.testng.TestNG.run(TestNG.java:996)at org.testng.remote.AbstractRemoteTestNG.run(AbstractRemoteTestNG.java:114)at org.testng.remote.RemoteTestNG.initAndRun(RemoteTestNG.java:251)at org.testng.remote.RemoteTestNG.main(RemoteTestNG.java:77)]]>
            </full-stacktrace>
          </exception> <!-- java.lang.AssertionError -->
          <reporter-output>
            <line>
              <![CDATA[方法<TestCase>执行失败，重试第2次]]>
            </line>
          </reporter-output>
        </test-method> <!-- TestCase -->
        <test-method status="SKIP" signature="TestCase(api.TestCase)[pri:0, instance:apitest.ApiTestNgTest@2e55dd0c]" name="TestCase" duration-ms="22" started-at="2018-01-21T16:10:21Z" data-provider="exceldata" finished-at="2018-01-21T16:10:21Z">
          <params>
            <param index="0">
              <value>
                <![CDATA[TestCase [type=get, url=http://59.110.139.20:8080/goods/UserServlet?method=loginMobile&loginname=test1&loginpass=test1, params=null, header=token=11;user=123;, result=null, check=$.code=1, correlation=id=$.uid]]]>
              </value>
            </param>
          </params>
          <exception class="java.lang.AssertionError">
            <message>
              <![CDATA[expected [true] but found [false]]]>
            </message>
            <full-stacktrace>
              <![CDATA[java.lang.AssertionError: expected [true] but found [false]at org.testng.Assert.fail(Assert.java:96)at org.testng.Assert.failNotEquals(Assert.java:776)at org.testng.Assert.assertTrue(Assert.java:44)at org.testng.Assert.assertTrue(Assert.java:54)at apitest.ApiTestNgTest.TestCase(ApiTestNgTest.java:42)at sun.reflect.NativeMethodAccessorImpl.invoke0(Native Method)at sun.reflect.NativeMethodAccessorImpl.invoke(NativeMethodAccessorImpl.java:62)at sun.reflect.DelegatingMethodAccessorImpl.invoke(DelegatingMethodAccessorImpl.java:43)at java.lang.reflect.Method.invoke(Method.java:483)at org.testng.internal.MethodInvocationHelper.invokeMethod(MethodInvocationHelper.java:124)at org.testng.internal.Invoker.invokeMethod(Invoker.java:571)at org.testng.internal.Invoker.retryFailed(Invoker.java:829)at org.testng.internal.Invoker.invokeTestMethods(Invoker.java:1000)at org.testng.internal.TestMethodWorker.invokeTestMethods(TestMethodWorker.java:125)at org.testng.internal.TestMethodWorker.run(TestMethodWorker.java:109)at org.testng.TestRunner.privateRun(TestRunner.java:648)at org.testng.TestRunner.run(TestRunner.java:505)at org.testng.SuiteRunner.runTest(SuiteRunner.java:455)at org.testng.SuiteRunner.runSequentially(SuiteRunner.java:450)at org.testng.SuiteRunner.privateRun(SuiteRunner.java:415)at org.testng.SuiteRunner.run(SuiteRunner.java:364)at org.testng.SuiteRunnerWorker.runSuite(SuiteRunnerWorker.java:52)at org.testng.SuiteRunnerWorker.run(SuiteRunnerWorker.java:84)at org.testng.TestNG.runSuitesSequentially(TestNG.java:1187)at org.testng.TestNG.runSuitesLocally(TestNG.java:1116)at org.testng.TestNG.runSuites(TestNG.java:1028)at org.testng.TestNG.run(TestNG.java:996)at org.testng.remote.AbstractRemoteTestNG.run(AbstractRemoteTestNG.java:114)at org.testng.remote.RemoteTestNG.initAndRun(RemoteTestNG.java:251)at org.testng.remote.RemoteTestNG.main(RemoteTestNG.java:77)]]>
            </full-stacktrace>
          </exception> <!-- java.lang.AssertionError -->
          <reporter-output>
            <line>
              <![CDATA[方法<TestCase>执行失败，重试第3次]]>
            </line>
          </reporter-output>
        </test-method> <!-- TestCase -->
        <test-method status="FAIL" signature="TestCase(api.TestCase)[pri:0, instance:apitest.ApiTestNgTest@2e55dd0c]" name="TestCase" duration-ms="32" started-at="2018-01-21T16:11:07Z" data-provider="exceldata" finished-at="2018-01-21T16:11:07Z">
          <params>
            <param index="0">
              <value>
                <![CDATA[TestCase [type=get, url=http://59.110.139.20:8080/goods/UserServlet?method=loginMobile&loginname=test1&loginpass=test1, params=null, header=token=11;user=123;, result=null, check=$.code=1, correlation=id=$.uid]]]>
              </value>
            </param>
          </params>
          <exception class="java.lang.AssertionError">
            <message>
              <![CDATA[expected [true] but found [false]]]>
            </message>
            <full-stacktrace>
              <![CDATA[java.lang.AssertionError: expected [true] but found [false]at org.testng.Assert.fail(Assert.java:96)at org.testng.Assert.failNotEquals(Assert.java:776)at org.testng.Assert.assertTrue(Assert.java:44)at org.testng.Assert.assertTrue(Assert.java:54)at apitest.ApiTestNgTest.TestCase(ApiTestNgTest.java:42)at sun.reflect.NativeMethodAccessorImpl.invoke0(Native Method)at sun.reflect.NativeMethodAccessorImpl.invoke(NativeMethodAccessorImpl.java:62)at sun.reflect.DelegatingMethodAccessorImpl.invoke(DelegatingMethodAccessorImpl.java:43)at java.lang.reflect.Method.invoke(Method.java:483)at org.testng.internal.MethodInvocationHelper.invokeMethod(MethodInvocationHelper.java:124)at org.testng.internal.Invoker.invokeMethod(Invoker.java:571)at org.testng.internal.Invoker.retryFailed(Invoker.java:829)at org.testng.internal.Invoker.invokeTestMethods(Invoker.java:1000)at org.testng.internal.TestMethodWorker.invokeTestMethods(TestMethodWorker.java:125)at org.testng.internal.TestMethodWorker.run(TestMethodWorker.java:109)at org.testng.TestRunner.privateRun(TestRunner.java:648)at org.testng.TestRunner.run(TestRunner.java:505)at org.testng.SuiteRunner.runTest(SuiteRunner.java:455)at org.testng.SuiteRunner.runSequentially(SuiteRunner.java:450)at org.testng.SuiteRunner.privateRun(SuiteRunner.java:415)at org.testng.SuiteRunner.run(SuiteRunner.java:364)at org.testng.SuiteRunnerWorker.runSuite(SuiteRunnerWorker.java:52)at org.testng.SuiteRunnerWorker.run(SuiteRunnerWorker.java:84)at org.testng.TestNG.runSuitesSequentially(TestNG.java:1187)at org.testng.TestNG.runSuitesLocally(TestNG.java:1116)at org.testng.TestNG.runSuites(TestNG.java:1028)at org.testng.TestNG.run(TestNG.java:996)at org.testng.remote.AbstractRemoteTestNG.run(AbstractRemoteTestNG.java:114)at org.testng.remote.RemoteTestNG.initAndRun(RemoteTestNG.java:251)at org.testng.remote.RemoteTestNG.main(RemoteTestNG.java:77)]]>
            </full-stacktrace>
          </exception> <!-- java.lang.AssertionError -->
          <reporter-output>
          </reporter-output>
        </test-method> <!-- TestCase -->
        <test-method status="SKIP" signature="TestCase(api.TestCase)[pri:0, instance:apitest.ApiTestNgTest@2e55dd0c]" name="TestCase" duration-ms="31" started-at="2018-01-21T16:11:16Z" data-provider="exceldata" finished-at="2018-01-21T16:11:16Z">
          <params>
            <param index="0">
              <value>
                <![CDATA[TestCase [type=postjson, url=http://59.110.139.20:8080/goods/json2, params={"count":10}, header=token=61b3590090982a0185dda9d3bd793b46, result=null, check=null, correlation=name_*=$..name;pwd_*=$..pwd]]]>
              </value>
            </param>
          </params>
          <exception class="java.lang.AssertionError">
            <message>
              <![CDATA[expected [true] but found [false]]]>
            </message>
            <full-stacktrace>
              <![CDATA[java.lang.AssertionError: expected [true] but found [false]at org.testng.Assert.fail(Assert.java:96)at org.testng.Assert.failNotEquals(Assert.java:776)at org.testng.Assert.assertTrue(Assert.java:44)at org.testng.Assert.assertTrue(Assert.java:54)at apitest.ApiTestNgTest.TestCase(ApiTestNgTest.java:42)at sun.reflect.NativeMethodAccessorImpl.invoke0(Native Method)at sun.reflect.NativeMethodAccessorImpl.invoke(NativeMethodAccessorImpl.java:62)at sun.reflect.DelegatingMethodAccessorImpl.invoke(DelegatingMethodAccessorImpl.java:43)at java.lang.reflect.Method.invoke(Method.java:483)at org.testng.internal.MethodInvocationHelper.invokeMethod(MethodInvocationHelper.java:124)at org.testng.internal.Invoker.invokeMethod(Invoker.java:571)at org.testng.internal.Invoker.invokeTestMethod(Invoker.java:707)at org.testng.internal.Invoker.invokeTestMethods(Invoker.java:979)at org.testng.internal.TestMethodWorker.invokeTestMethods(TestMethodWorker.java:125)at org.testng.internal.TestMethodWorker.run(TestMethodWorker.java:109)at org.testng.TestRunner.privateRun(TestRunner.java:648)at org.testng.TestRunner.run(TestRunner.java:505)at org.testng.SuiteRunner.runTest(SuiteRunner.java:455)at org.testng.SuiteRunner.runSequentially(SuiteRunner.java:450)at org.testng.SuiteRunner.privateRun(SuiteRunner.java:415)at org.testng.SuiteRunner.run(SuiteRunner.java:364)at org.testng.SuiteRunnerWorker.runSuite(SuiteRunnerWorker.java:52)at org.testng.SuiteRunnerWorker.run(SuiteRunnerWorker.java:84)at org.testng.TestNG.runSuitesSequentially(TestNG.java:1187)at org.testng.TestNG.runSuitesLocally(TestNG.java:1116)at org.testng.TestNG.runSuites(TestNG.java:1028)at org.testng.TestNG.run(TestNG.java:996)at org.testng.remote.AbstractRemoteTestNG.run(AbstractRemoteTestNG.java:114)at org.testng.remote.RemoteTestNG.initAndRun(RemoteTestNG.java:251)at org.testng.remote.RemoteTestNG.main(RemoteTestNG.java:77)]]>
            </full-stacktrace>
          </exception> <!-- java.lang.AssertionError -->
          <reporter-output>
            <line>
              <![CDATA[方法<TestCase>执行失败，重试第1次]]>
            </line>
          </reporter-output>
        </test-method> <!-- TestCase -->
        <test-method status="SKIP" signature="TestCase(api.TestCase)[pri:0, instance:apitest.ApiTestNgTest@2e55dd0c]" name="TestCase" duration-ms="19" started-at="2018-01-21T16:11:21Z" data-provider="exceldata" finished-at="2018-01-21T16:11:21Z">
          <params>
            <param index="0">
              <value>
                <![CDATA[TestCase [type=postjson, url=http://59.110.139.20:8080/goods/json2, params={"count":10}, header=token=61b3590090982a0185dda9d3bd793b46, result=null, check=null, correlation=name_*=$..name;pwd_*=$..pwd]]]>
              </value>
            </param>
          </params>
          <exception class="java.lang.AssertionError">
            <message>
              <![CDATA[expected [true] but found [false]]]>
            </message>
            <full-stacktrace>
              <![CDATA[java.lang.AssertionError: expected [true] but found [false]at org.testng.Assert.fail(Assert.java:96)at org.testng.Assert.failNotEquals(Assert.java:776)at org.testng.Assert.assertTrue(Assert.java:44)at org.testng.Assert.assertTrue(Assert.java:54)at apitest.ApiTestNgTest.TestCase(ApiTestNgTest.java:42)at sun.reflect.NativeMethodAccessorImpl.invoke0(Native Method)at sun.reflect.NativeMethodAccessorImpl.invoke(NativeMethodAccessorImpl.java:62)at sun.reflect.DelegatingMethodAccessorImpl.invoke(DelegatingMethodAccessorImpl.java:43)at java.lang.reflect.Method.invoke(Method.java:483)at org.testng.internal.MethodInvocationHelper.invokeMethod(MethodInvocationHelper.java:124)at org.testng.internal.Invoker.invokeMethod(Invoker.java:571)at org.testng.internal.Invoker.retryFailed(Invoker.java:829)at org.testng.internal.Invoker.invokeTestMethods(Invoker.java:1000)at org.testng.internal.TestMethodWorker.invokeTestMethods(TestMethodWorker.java:125)at org.testng.internal.TestMethodWorker.run(TestMethodWorker.java:109)at org.testng.TestRunner.privateRun(TestRunner.java:648)at org.testng.TestRunner.run(TestRunner.java:505)at org.testng.SuiteRunner.runTest(SuiteRunner.java:455)at org.testng.SuiteRunner.runSequentially(SuiteRunner.java:450)at org.testng.SuiteRunner.privateRun(SuiteRunner.java:415)at org.testng.SuiteRunner.run(SuiteRunner.java:364)at org.testng.SuiteRunnerWorker.runSuite(SuiteRunnerWorker.java:52)at org.testng.SuiteRunnerWorker.run(SuiteRunnerWorker.java:84)at org.testng.TestNG.runSuitesSequentially(TestNG.java:1187)at org.testng.TestNG.runSuitesLocally(TestNG.java:1116)at org.testng.TestNG.runSuites(TestNG.java:1028)at org.testng.TestNG.run(TestNG.java:996)at org.testng.remote.AbstractRemoteTestNG.run(AbstractRemoteTestNG.java:114)at org.testng.remote.RemoteTestNG.initAndRun(RemoteTestNG.java:251)at org.testng.remote.RemoteTestNG.main(RemoteTestNG.java:77)]]>
            </full-stacktrace>
          </exception> <!-- java.lang.AssertionError -->
          <reporter-output>
            <line>
              <![CDATA[方法<TestCase>执行失败，重试第2次]]>
            </line>
          </reporter-output>
        </test-method> <!-- TestCase -->
        <test-method status="SKIP" signature="TestCase(api.TestCase)[pri:0, instance:apitest.ApiTestNgTest@2e55dd0c]" name="TestCase" duration-ms="17" started-at="2018-01-21T16:11:21Z" data-provider="exceldata" finished-at="2018-01-21T16:11:21Z">
          <params>
            <param index="0">
              <value>
                <![CDATA[TestCase [type=postjson, url=http://59.110.139.20:8080/goods/json2, params={"count":10}, header=token=61b3590090982a0185dda9d3bd793b46, result=null, check=null, correlation=name_*=$..name;pwd_*=$..pwd]]]>
              </value>
            </param>
          </params>
          <exception class="java.lang.AssertionError">
            <message>
              <![CDATA[expected [true] but found [false]]]>
            </message>
            <full-stacktrace>
              <![CDATA[java.lang.AssertionError: expected [true] but found [false]at org.testng.Assert.fail(Assert.java:96)at org.testng.Assert.failNotEquals(Assert.java:776)at org.testng.Assert.assertTrue(Assert.java:44)at org.testng.Assert.assertTrue(Assert.java:54)at apitest.ApiTestNgTest.TestCase(ApiTestNgTest.java:42)at sun.reflect.NativeMethodAccessorImpl.invoke0(Native Method)at sun.reflect.NativeMethodAccessorImpl.invoke(NativeMethodAccessorImpl.java:62)at sun.reflect.DelegatingMethodAccessorImpl.invoke(DelegatingMethodAccessorImpl.java:43)at java.lang.reflect.Method.invoke(Method.java:483)at org.testng.internal.MethodInvocationHelper.invokeMethod(MethodInvocationHelper.java:124)at org.testng.internal.Invoker.invokeMethod(Invoker.java:571)at org.testng.internal.Invoker.retryFailed(Invoker.java:829)at org.testng.internal.Invoker.invokeTestMethods(Invoker.java:1000)at org.testng.internal.TestMethodWorker.invokeTestMethods(TestMethodWorker.java:125)at org.testng.internal.TestMethodWorker.run(TestMethodWorker.java:109)at org.testng.TestRunner.privateRun(TestRunner.java:648)at org.testng.TestRunner.run(TestRunner.java:505)at org.testng.SuiteRunner.runTest(SuiteRunner.java:455)at org.testng.SuiteRunner.runSequentially(SuiteRunner.java:450)at org.testng.SuiteRunner.privateRun(SuiteRunner.java:415)at org.testng.SuiteRunner.run(SuiteRunner.java:364)at org.testng.SuiteRunnerWorker.runSuite(SuiteRunnerWorker.java:52)at org.testng.SuiteRunnerWorker.run(SuiteRunnerWorker.java:84)at org.testng.TestNG.runSuitesSequentially(TestNG.java:1187)at org.testng.TestNG.runSuitesLocally(TestNG.java:1116)at org.testng.TestNG.runSuites(TestNG.java:1028)at org.testng.TestNG.run(TestNG.java:996)at org.testng.remote.AbstractRemoteTestNG.run(AbstractRemoteTestNG.java:114)at org.testng.remote.RemoteTestNG.initAndRun(RemoteTestNG.java:251)at org.testng.remote.RemoteTestNG.main(RemoteTestNG.java:77)]]>
            </full-stacktrace>
          </exception> <!-- java.lang.AssertionError -->
          <reporter-output>
            <line>
              <![CDATA[方法<TestCase>执行失败，重试第3次]]>
            </line>
          </reporter-output>
        </test-method> <!-- TestCase -->
        <test-method status="FAIL" signature="TestCase(api.TestCase)[pri:0, instance:apitest.ApiTestNgTest@2e55dd0c]" name="TestCase" duration-ms="18" started-at="2018-01-21T16:11:21Z" data-provider="exceldata" finished-at="2018-01-21T16:11:21Z">
          <params>
            <param index="0">
              <value>
                <![CDATA[TestCase [type=postjson, url=http://59.110.139.20:8080/goods/json2, params={"count":10}, header=token=61b3590090982a0185dda9d3bd793b46, result=null, check=null, correlation=name_*=$..name;pwd_*=$..pwd]]]>
              </value>
            </param>
          </params>
          <exception class="java.lang.AssertionError">
            <message>
              <![CDATA[expected [true] but found [false]]]>
            </message>
            <full-stacktrace>
              <![CDATA[java.lang.AssertionError: expected [true] but found [false]at org.testng.Assert.fail(Assert.java:96)at org.testng.Assert.failNotEquals(Assert.java:776)at org.testng.Assert.assertTrue(Assert.java:44)at org.testng.Assert.assertTrue(Assert.java:54)at apitest.ApiTestNgTest.TestCase(ApiTestNgTest.java:42)at sun.reflect.NativeMethodAccessorImpl.invoke0(Native Method)at sun.reflect.NativeMethodAccessorImpl.invoke(NativeMethodAccessorImpl.java:62)at sun.reflect.DelegatingMethodAccessorImpl.invoke(DelegatingMethodAccessorImpl.java:43)at java.lang.reflect.Method.invoke(Method.java:483)at org.testng.internal.MethodInvocationHelper.invokeMethod(MethodInvocationHelper.java:124)at org.testng.internal.Invoker.invokeMethod(Invoker.java:571)at org.testng.internal.Invoker.retryFailed(Invoker.java:829)at org.testng.internal.Invoker.invokeTestMethods(Invoker.java:1000)at org.testng.internal.TestMethodWorker.invokeTestMethods(TestMethodWorker.java:125)at org.testng.internal.TestMethodWorker.run(TestMethodWorker.java:109)at org.testng.TestRunner.privateRun(TestRunner.java:648)at org.testng.TestRunner.run(TestRunner.java:505)at org.testng.SuiteRunner.runTest(SuiteRunner.java:455)at org.testng.SuiteRunner.runSequentially(SuiteRunner.java:450)at org.testng.SuiteRunner.privateRun(SuiteRunner.java:415)at org.testng.SuiteRunner.run(SuiteRunner.java:364)at org.testng.SuiteRunnerWorker.runSuite(SuiteRunnerWorker.java:52)at org.testng.SuiteRunnerWorker.run(SuiteRunnerWorker.java:84)at org.testng.TestNG.runSuitesSequentially(TestNG.java:1187)at org.testng.TestNG.runSuitesLocally(TestNG.java:1116)at org.testng.TestNG.runSuites(TestNG.java:1028)at org.testng.TestNG.run(TestNG.java:996)at org.testng.remote.AbstractRemoteTestNG.run(AbstractRemoteTestNG.java:114)at org.testng.remote.RemoteTestNG.initAndRun(RemoteTestNG.java:251)at org.testng.remote.RemoteTestNG.main(RemoteTestNG.java:77)]]>
            </full-stacktrace>
          </exception> <!-- java.lang.AssertionError -->
          <reporter-output>
          </reporter-output>
        </test-method> <!-- TestCase -->
        <test-method status="SKIP" signature="TestCase(api.TestCase)[pri:0, instance:apitest.ApiTestNgTest@2e55dd0c]" name="TestCase" duration-ms="59" started-at="2018-01-21T16:11:21Z" data-provider="exceldata" finished-at="2018-01-21T16:11:21Z">
          <params>
            <param index="0">
              <value>
                <![CDATA[TestCase [type=get, url=http://www.baidu.com?pid=E2BBEDC09FAA4406B8D85C96DF6281CF&test=testfan0, params=null, header=null, result=null, check=null, correlation=null]]]>
              </value>
            </param>
          </params>
          <exception class="java.lang.AssertionError">
            <message>
              <![CDATA[expected [true] but found [false]]]>
            </message>
            <full-stacktrace>
              <![CDATA[java.lang.AssertionError: expected [true] but found [false]at org.testng.Assert.fail(Assert.java:96)at org.testng.Assert.failNotEquals(Assert.java:776)at org.testng.Assert.assertTrue(Assert.java:44)at org.testng.Assert.assertTrue(Assert.java:54)at apitest.ApiTestNgTest.TestCase(ApiTestNgTest.java:42)at sun.reflect.NativeMethodAccessorImpl.invoke0(Native Method)at sun.reflect.NativeMethodAccessorImpl.invoke(NativeMethodAccessorImpl.java:62)at sun.reflect.DelegatingMethodAccessorImpl.invoke(DelegatingMethodAccessorImpl.java:43)at java.lang.reflect.Method.invoke(Method.java:483)at org.testng.internal.MethodInvocationHelper.invokeMethod(MethodInvocationHelper.java:124)at org.testng.internal.Invoker.invokeMethod(Invoker.java:571)at org.testng.internal.Invoker.invokeTestMethod(Invoker.java:707)at org.testng.internal.Invoker.invokeTestMethods(Invoker.java:979)at org.testng.internal.TestMethodWorker.invokeTestMethods(TestMethodWorker.java:125)at org.testng.internal.TestMethodWorker.run(TestMethodWorker.java:109)at org.testng.TestRunner.privateRun(TestRunner.java:648)at org.testng.TestRunner.run(TestRunner.java:505)at org.testng.SuiteRunner.runTest(SuiteRunner.java:455)at org.testng.SuiteRunner.runSequentially(SuiteRunner.java:450)at org.testng.SuiteRunner.privateRun(SuiteRunner.java:415)at org.testng.SuiteRunner.run(SuiteRunner.java:364)at org.testng.SuiteRunnerWorker.runSuite(SuiteRunnerWorker.java:52)at org.testng.SuiteRunnerWorker.run(SuiteRunnerWorker.java:84)at org.testng.TestNG.runSuitesSequentially(TestNG.java:1187)at org.testng.TestNG.runSuitesLocally(TestNG.java:1116)at org.testng.TestNG.runSuites(TestNG.java:1028)at org.testng.TestNG.run(TestNG.java:996)at org.testng.remote.AbstractRemoteTestNG.run(AbstractRemoteTestNG.java:114)at org.testng.remote.RemoteTestNG.initAndRun(RemoteTestNG.java:251)at org.testng.remote.RemoteTestNG.main(RemoteTestNG.java:77)]]>
            </full-stacktrace>
          </exception> <!-- java.lang.AssertionError -->
          <reporter-output>
            <line>
              <![CDATA[方法<TestCase>执行失败，重试第1次]]>
            </line>
          </reporter-output>
        </test-method> <!-- TestCase -->
        <test-method status="SKIP" signature="TestCase(api.TestCase)[pri:0, instance:apitest.ApiTestNgTest@2e55dd0c]" name="TestCase" duration-ms="78" started-at="2018-01-21T16:11:21Z" data-provider="exceldata" finished-at="2018-01-21T16:11:21Z">
          <params>
            <param index="0">
              <value>
                <![CDATA[TestCase [type=get, url=http://www.baidu.com?pid=E2BBEDC09FAA4406B8D85C96DF6281CF&test=testfan0, params=null, header=null, result=null, check=null, correlation=null]]]>
              </value>
            </param>
          </params>
          <exception class="java.lang.AssertionError">
            <message>
              <![CDATA[expected [true] but found [false]]]>
            </message>
            <full-stacktrace>
              <![CDATA[java.lang.AssertionError: expected [true] but found [false]at org.testng.Assert.fail(Assert.java:96)at org.testng.Assert.failNotEquals(Assert.java:776)at org.testng.Assert.assertTrue(Assert.java:44)at org.testng.Assert.assertTrue(Assert.java:54)at apitest.ApiTestNgTest.TestCase(ApiTestNgTest.java:42)at sun.reflect.NativeMethodAccessorImpl.invoke0(Native Method)at sun.reflect.NativeMethodAccessorImpl.invoke(NativeMethodAccessorImpl.java:62)at sun.reflect.DelegatingMethodAccessorImpl.invoke(DelegatingMethodAccessorImpl.java:43)at java.lang.reflect.Method.invoke(Method.java:483)at org.testng.internal.MethodInvocationHelper.invokeMethod(MethodInvocationHelper.java:124)at org.testng.internal.Invoker.invokeMethod(Invoker.java:571)at org.testng.internal.Invoker.retryFailed(Invoker.java:829)at org.testng.internal.Invoker.invokeTestMethods(Invoker.java:1000)at org.testng.internal.TestMethodWorker.invokeTestMethods(TestMethodWorker.java:125)at org.testng.internal.TestMethodWorker.run(TestMethodWorker.java:109)at org.testng.TestRunner.privateRun(TestRunner.java:648)at org.testng.TestRunner.run(TestRunner.java:505)at org.testng.SuiteRunner.runTest(SuiteRunner.java:455)at org.testng.SuiteRunner.runSequentially(SuiteRunner.java:450)at org.testng.SuiteRunner.privateRun(SuiteRunner.java:415)at org.testng.SuiteRunner.run(SuiteRunner.java:364)at org.testng.SuiteRunnerWorker.runSuite(SuiteRunnerWorker.java:52)at org.testng.SuiteRunnerWorker.run(SuiteRunnerWorker.java:84)at org.testng.TestNG.runSuitesSequentially(TestNG.java:1187)at org.testng.TestNG.runSuitesLocally(TestNG.java:1116)at org.testng.TestNG.runSuites(TestNG.java:1028)at org.testng.TestNG.run(TestNG.java:996)at org.testng.remote.AbstractRemoteTestNG.run(AbstractRemoteTestNG.java:114)at org.testng.remote.RemoteTestNG.initAndRun(RemoteTestNG.java:251)at org.testng.remote.RemoteTestNG.main(RemoteTestNG.java:77)]]>
            </full-stacktrace>
          </exception> <!-- java.lang.AssertionError -->
          <reporter-output>
            <line>
              <![CDATA[方法<TestCase>执行失败，重试第2次]]>
            </line>
          </reporter-output>
        </test-method> <!-- TestCase -->
        <test-method status="SKIP" signature="TestCase(api.TestCase)[pri:0, instance:apitest.ApiTestNgTest@2e55dd0c]" name="TestCase" duration-ms="27" started-at="2018-01-21T16:11:21Z" data-provider="exceldata" finished-at="2018-01-21T16:11:21Z">
          <params>
            <param index="0">
              <value>
                <![CDATA[TestCase [type=get, url=http://www.baidu.com?pid=E2BBEDC09FAA4406B8D85C96DF6281CF&test=testfan0, params=null, header=null, result=null, check=null, correlation=null]]]>
              </value>
            </param>
          </params>
          <exception class="java.lang.AssertionError">
            <message>
              <![CDATA[expected [true] but found [false]]]>
            </message>
            <full-stacktrace>
              <![CDATA[java.lang.AssertionError: expected [true] but found [false]at org.testng.Assert.fail(Assert.java:96)at org.testng.Assert.failNotEquals(Assert.java:776)at org.testng.Assert.assertTrue(Assert.java:44)at org.testng.Assert.assertTrue(Assert.java:54)at apitest.ApiTestNgTest.TestCase(ApiTestNgTest.java:42)at sun.reflect.NativeMethodAccessorImpl.invoke0(Native Method)at sun.reflect.NativeMethodAccessorImpl.invoke(NativeMethodAccessorImpl.java:62)at sun.reflect.DelegatingMethodAccessorImpl.invoke(DelegatingMethodAccessorImpl.java:43)at java.lang.reflect.Method.invoke(Method.java:483)at org.testng.internal.MethodInvocationHelper.invokeMethod(MethodInvocationHelper.java:124)at org.testng.internal.Invoker.invokeMethod(Invoker.java:571)at org.testng.internal.Invoker.retryFailed(Invoker.java:829)at org.testng.internal.Invoker.invokeTestMethods(Invoker.java:1000)at org.testng.internal.TestMethodWorker.invokeTestMethods(TestMethodWorker.java:125)at org.testng.internal.TestMethodWorker.run(TestMethodWorker.java:109)at org.testng.TestRunner.privateRun(TestRunner.java:648)at org.testng.TestRunner.run(TestRunner.java:505)at org.testng.SuiteRunner.runTest(SuiteRunner.java:455)at org.testng.SuiteRunner.runSequentially(SuiteRunner.java:450)at org.testng.SuiteRunner.privateRun(SuiteRunner.java:415)at org.testng.SuiteRunner.run(SuiteRunner.java:364)at org.testng.SuiteRunnerWorker.runSuite(SuiteRunnerWorker.java:52)at org.testng.SuiteRunnerWorker.run(SuiteRunnerWorker.java:84)at org.testng.TestNG.runSuitesSequentially(TestNG.java:1187)at org.testng.TestNG.runSuitesLocally(TestNG.java:1116)at org.testng.TestNG.runSuites(TestNG.java:1028)at org.testng.TestNG.run(TestNG.java:996)at org.testng.remote.AbstractRemoteTestNG.run(AbstractRemoteTestNG.java:114)at org.testng.remote.RemoteTestNG.initAndRun(RemoteTestNG.java:251)at org.testng.remote.RemoteTestNG.main(RemoteTestNG.java:77)]]>
            </full-stacktrace>
          </exception> <!-- java.lang.AssertionError -->
          <reporter-output>
            <line>
              <![CDATA[方法<TestCase>执行失败，重试第3次]]>
            </line>
          </reporter-output>
        </test-method> <!-- TestCase -->
        <test-method status="FAIL" signature="TestCase(api.TestCase)[pri:0, instance:apitest.ApiTestNgTest@2e55dd0c]" name="TestCase" duration-ms="26" started-at="2018-01-21T16:11:21Z" data-provider="exceldata" finished-at="2018-01-21T16:11:21Z">
          <params>
            <param index="0">
              <value>
                <![CDATA[TestCase [type=get, url=http://www.baidu.com?pid=E2BBEDC09FAA4406B8D85C96DF6281CF&test=testfan0, params=null, header=null, result=null, check=null, correlation=null]]]>
              </value>
            </param>
          </params>
          <exception class="java.lang.AssertionError">
            <message>
              <![CDATA[expected [true] but found [false]]]>
            </message>
            <full-stacktrace>
              <![CDATA[java.lang.AssertionError: expected [true] but found [false]at org.testng.Assert.fail(Assert.java:96)at org.testng.Assert.failNotEquals(Assert.java:776)at org.testng.Assert.assertTrue(Assert.java:44)at org.testng.Assert.assertTrue(Assert.java:54)at apitest.ApiTestNgTest.TestCase(ApiTestNgTest.java:42)at sun.reflect.NativeMethodAccessorImpl.invoke0(Native Method)at sun.reflect.NativeMethodAccessorImpl.invoke(NativeMethodAccessorImpl.java:62)at sun.reflect.DelegatingMethodAccessorImpl.invoke(DelegatingMethodAccessorImpl.java:43)at java.lang.reflect.Method.invoke(Method.java:483)at org.testng.internal.MethodInvocationHelper.invokeMethod(MethodInvocationHelper.java:124)at org.testng.internal.Invoker.invokeMethod(Invoker.java:571)at org.testng.internal.Invoker.retryFailed(Invoker.java:829)at org.testng.internal.Invoker.invokeTestMethods(Invoker.java:1000)at org.testng.internal.TestMethodWorker.invokeTestMethods(TestMethodWorker.java:125)at org.testng.internal.TestMethodWorker.run(TestMethodWorker.java:109)at org.testng.TestRunner.privateRun(TestRunner.java:648)at org.testng.TestRunner.run(TestRunner.java:505)at org.testng.SuiteRunner.runTest(SuiteRunner.java:455)at org.testng.SuiteRunner.runSequentially(SuiteRunner.java:450)at org.testng.SuiteRunner.privateRun(SuiteRunner.java:415)at org.testng.SuiteRunner.run(SuiteRunner.java:364)at org.testng.SuiteRunnerWorker.runSuite(SuiteRunnerWorker.java:52)at org.testng.SuiteRunnerWorker.run(SuiteRunnerWorker.java:84)at org.testng.TestNG.runSuitesSequentially(TestNG.java:1187)at org.testng.TestNG.runSuitesLocally(TestNG.java:1116)at org.testng.TestNG.runSuites(TestNG.java:1028)at org.testng.TestNG.run(TestNG.java:996)at org.testng.remote.AbstractRemoteTestNG.run(AbstractRemoteTestNG.java:114)at org.testng.remote.RemoteTestNG.initAndRun(RemoteTestNG.java:251)at org.testng.remote.RemoteTestNG.main(RemoteTestNG.java:77)]]>
            </full-stacktrace>
          </exception> <!-- java.lang.AssertionError -->
          <reporter-output>
          </reporter-output>
        </test-method> <!-- TestCase -->
      </class> <!-- apitest.ApiTestNgTest -->
    </test> <!-- testDemo1 -->
  </suite> <!-- testproj -->
</testng-results>
